Workbook

Sheet Executive Dashboard
A1: Wysker Watch — Executive Launch Dashboard
A3: Live view of task status, bucket readiness, sub-bucket progress, and formal launch gates
A5: TRACKED ITEMS | D5: COMPLETE | G5: IN PROGRESS | J5: BLOCKERS OPEN | M5: GATES PASSED
A6: =COUNTIF('Launch Plan'!$K$5:$K$126,"Complete")+COUNTIF('Launch Plan'!$K$5:$K$126,"In Progress")+COUNTIF('Launch Plan'!$K$5:$K$126,"Not Started") -> 113 | D6: =COUNTIF('Launch Plan'!$K$5:$K$126,"Complete") -> 22 | G6: =COUNTIF('Launch Plan'!$K$5:$K$126,"In Progress") -> 2 | J6: =COUNTIFS('Launch Plan'!$L$5:$L$126,"Yes",'Launch Plan'!$K$5:$K$126,"<>Complete") -> 35 | M6: =COUNTIFS('Launch Plan'!$E$5:$E$126,"GATE",'Launch Plan'!$K$5:$K$126,"Complete")&" / "&COUNTIF('Launch Plan'!$E$5:$E$126,"GATE") -> 0 / 15
A10: OVERALL STATUS MIX | H10: BUCKET READINESS
A12: Status | B12: Count | H12: Bucket | I12: Total | J12: Complete | K12: In Progress | L12: Not Started | M12: % Complete | N12: Signal
A13: Complete | B13: =COUNTIF('Launch Plan'!$K$5:$K$126,A13) -> 22 | H13: PWA | I13: =COUNTIFS('Launch Plan'!$A$5:$A$126,H13,'Launch Plan'!$K$5:$K$126,"Complete")+COUNTIFS('Launch Plan'!$A$5:$A$126,H13,'Launch Plan'!$K$5:$K$126,"In Progress")+COUNTIFS('Launch Plan'!$A$5:$A$126,H13,'Launch Plan'!$K$5:$K$126,"Not Started") -> 34 | J13: =COUNTIFS('Launch Plan'!$A$5:$A$126,H13,'Launch Plan'!$K$5:$K$126,"Complete") -> 15 | K13: =COUNTIFS('Launch Plan'!$A$5:$A$126,H13,'Launch Plan'!$K$5:$K$126,"In Progress") -> 1 | L13: =COUNTIFS('Launch Plan'!$A$5:$A$126,H13,'Launch Plan'!$K$5:$K$126,"Not Started") -> 18 | M13: =IFERROR(J13/I13,0) -> 0.44117647 | N13: =IF(M13=1,"READY",IF(K13>0,"MOVING",IF(M13>0,"PARTIAL","NOT STARTED"))) -> MOVING
A14: In Progress | B14: =COUNTIF('Launch Plan'!$K$5:$K$126,A14) -> 2 | H14: Analytics & Support | I14: =COUNTIFS('Launch Plan'!$A$5:$A$126,H14,'Launch Plan'!$K$5:$K$126,"Complete")+COUNTIFS('Launch Plan'!$A$5:$A$126,H14,'Launch Plan'!$K$5:$K$126,"In Progress")+COUNTIFS('Launch Plan'!$A$5:$A$126,H14,'Launch Plan'!$K$5:$K$126,"Not Started") -> 5 | J14: =COUNTIFS('Launch Plan'!$A$5:$A$126,H14,'Launch Plan'!$K$5:$K$126,"Complete") -> 4 | K14: =COUNTIFS('Launch Plan'!$A$5:$A$126,H14,'Launch Plan'!$K$5:$K$126,"In Progress") -> 0 | L14: =COUNTIFS('Launch Plan'!$A$5:$A$126,H14,'Launch Plan'!$K$5:$K$126,"Not Started") -> 1 | M14: =IFERROR(J14/I14,0) -> 0.8 | N14: =IF(M14=1,"READY",IF(K14>0,"MOVING",IF(M14>0,"PARTIAL","NOT STARTED"))) -> PARTIAL
A15: Not Started | B15: =COUNTIF('Launch Plan'!$K$5:$K$126,A15) -> 89 | H15: User Funnel | I15: =COUNTIFS('Launch Plan'!$A$5:$A$126,H15,'Launch Plan'!$K$5:$K$126,"Complete")+COUNTIFS('Launch Plan'!$A$5:$A$126,H15,'Launch Plan'!$K$5:$K$126,"In Progress")+COUNTIFS('Launch Plan'!$A$5:$A$126,H15,'Launch Plan'!$K$5:$K$126,"Not Started") -> 1 | J15: =COUNTIFS('Launch Plan'!$A$5:$A$126,H15,'Launch Plan'!$K$5:$K$126,"Complete") -> 0 | K15: =COUNTIFS('Launch Plan'!$A$5:$A$126,H15,'Launch Plan'!$K$5:$K$126,"In Progress") -> 0 | L15: =COUNTIFS('Launch Plan'!$A$5:$A$126,H15,'Launch Plan'!$K$5:$K$126,"Not Started") -> 1 | M15: =IFERROR(J15/I15,0) -> 0 | N15: =IF(M15=1,"READY",IF(K15>0,"MOVING",IF(M15>0,"PARTIAL","NOT STARTED"))) -> NOT STARTED
H16: Social & Content | I16: =COUNTIFS('Launch Plan'!$A$5:$A$126,H16,'Launch Plan'!$K$5:$K$126,"Complete")+COUNTIFS('Launch Plan'!$A$5:$A$126,H16,'Launch Plan'!$K$5:$K$126,"In Progress")+COUNTIFS('Launch Plan'!$A$5:$A$126,H16,'Launch Plan'!$K$5:$K$126,"Not Started") -> 8 | J16: =COUNTIFS('Launch Plan'!$A$5:$A$126,H16,'Launch Plan'!$K$5:$K$126,"Complete") -> 0 | K16: =COUNTIFS('Launch Plan'!$A$5:$A$126,H16,'Launch Plan'!$K$5:$K$126,"In Progress") -> 1 | L16: =COUNTIFS('Launch Plan'!$A$5:$A$126,H16,'Launch Plan'!$K$5:$K$126,"Not Started") -> 7 | M16: =IFERROR(J16/I16,0) -> 0 | N16: =IF(M16=1,"READY",IF(K16>0,"MOVING",IF(M16>0,"PARTIAL","NOT STARTED"))) -> MOVING
H17: Business Readiness | I17: =COUNTIFS('Launch Plan'!$A$5:$A$126,H17,'Launch Plan'!$K$5:$K$126,"Complete")+COUNTIFS('Launch Plan'!$A$5:$A$126,H17,'Launch Plan'!$K$5:$K$126,"In Progress")+COUNTIFS('Launch Plan'!$A$5:$A$126,H17,'Launch Plan'!$K$5:$K$126,"Not Started") -> 9 | J17: =COUNTIFS('Launch Plan'!$A$5:$A$126,H17,'Launch Plan'!$K$5:$K$126,"Complete") -> 1 | K17: =COUNTIFS('Launch Plan'!$A$5:$A$126,H17,'Launch Plan'!$K$5:$K$126,"In Progress") -> 0 | L17: =COUNTIFS('Launch Plan'!$A$5:$A$126,H17,'Launch Plan'!$K$5:$K$126,"Not Started") -> 8 | M17: =IFERROR(J17/I17,0) -> 0.11111111 | N17: =IF(M17=1,"READY",IF(K17>0,"MOVING",IF(M17>0,"PARTIAL","NOT STARTED"))) -> PARTIAL
H18: Risk | I18: =COUNTIFS('Launch Plan'!$A$5:$A$126,H18,'Launch Plan'!$K$5:$K$126,"Complete")+COUNTIFS('Launch Plan'!$A$5:$A$126,H18,'Launch Plan'!$K$5:$K$126,"In Progress")+COUNTIFS('Launch Plan'!$A$5:$A$126,H18,'Launch Plan'!$K$5:$K$126,"Not Started") -> 14 | J18: =COUNTIFS('Launch Plan'!$A$5:$A$126,H18,'Launch Plan'!$K$5:$K$126,"Complete") -> 2 | K18: =COUNTIFS('Launch Plan'!$A$5:$A$126,H18,'Launch Plan'!$K$5:$K$126,"In Progress") -> 0 | L18: =COUNTIFS('Launch Plan'!$A$5:$A$126,H18,'Launch Plan'!$K$5:$K$126,"Not Started") -> 12 | M18: =IFERROR(J18/I18,0) -> 0.14285714 | N18: =IF(M18=1,"READY",IF(K18>0,"MOVING",IF(M18>0,"PARTIAL","NOT STARTED"))) -> PARTIAL
H19: Alpha | I19: =COUNTIFS('Launch Plan'!$A$5:$A$126,H19,'Launch Plan'!$K$5:$K$126,"Complete")+COUNTIFS('Launch Plan'!$A$5:$A$126,H19,'Launch Plan'!$K$5:$K$126,"In Progress")+COUNTIFS('Launch Plan'!$A$5:$A$126,H19,'Launch Plan'!$K$5:$K$126,"Not Started") -> 12 | J19: =COUNTIFS('Launch Plan'!$A$5:$A$126,H19,'Launch Plan'!$K$5:$K$126,"Complete") -> 0 | K19: =COUNTIFS('Launch Plan'!$A$5:$A$126,H19,'Launch Plan'!$K$5:$K$126,"In Progress") -> 0 | L19: =COUNTIFS('Launch Plan'!$A$5:$A$126,H19,'Launch Plan'!$K$5:$K$126,"Not Started") -> 12 | M19: =IFERROR(J19/I19,0) -> 0 | N19: =IF(M19=1,"READY",IF(K19>0,"MOVING",IF(M19>0,"PARTIAL","NOT STARTED"))) -> NOT STARTED
H20: Launch Day | I20: =COUNTIFS('Launch Plan'!$A$5:$A$126,H20,'Launch Plan'!$K$5:$K$126,"Complete")+COUNTIFS('Launch Plan'!$A$5:$A$126,H20,'Launch Plan'!$K$5:$K$126,"In Progress")+COUNTIFS('Launch Plan'!$A$5:$A$126,H20,'Launch Plan'!$K$5:$K$126,"Not Started") -> 10 | J20: =COUNTIFS('Launch Plan'!$A$5:$A$126,H20,'Launch Plan'!$K$5:$K$126,"Complete") -> 0 | K20: =COUNTIFS('Launch Plan'!$A$5:$A$126,H20,'Launch Plan'!$K$5:$K$126,"In Progress") -> 0 | L20: =COUNTIFS('Launch Plan'!$A$5:$A$126,H20,'Launch Plan'!$K$5:$K$126,"Not Started") -> 10 | M20: =IFERROR(J20/I20,0) -> 0 | N20: =IF(M20=1,"READY",IF(K20>0,"MOVING",IF(M20>0,"PARTIAL","NOT STARTED"))) -> NOT STARTED
H21: App Store | I21: =COUNTIFS('Launch Plan'!$A$5:$A$126,H21,'Launch Plan'!$K$5:$K$126,"Complete")+COUNTIFS('Launch Plan'!$A$5:$A$126,H21,'Launch Plan'!$K$5:$K$126,"In Progress")+COUNTIFS('Launch Plan'!$A$5:$A$126,H21,'Launch Plan'!$K$5:$K$126,"Not Started") -> 19 | J21: =COUNTIFS('Launch Plan'!$A$5:$A$126,H21,'Launch Plan'!$K$5:$K$126,"Complete") -> 0 | K21: =COUNTIFS('Launch Plan'!$A$5:$A$126,H21,'Launch Plan'!$K$5:$K$126,"In Progress") -> 0 | L21: =COUNTIFS('Launch Plan'!$A$5:$A$126,H21,'Launch Plan'!$K$5:$K$126,"Not Started") -> 19 | M21: =IFERROR(J21/I21,0) -> 0 | N21: =IF(M21=1,"READY",IF(K21>0,"MOVING",IF(M21>0,"PARTIAL","NOT STARTED"))) -> NOT STARTED
H22: Post-Launch Backlog | I22: =COUNTIFS('Launch Plan'!$A$5:$A$126,H22,'Launch Plan'!$K$5:$K$126,"Complete")+COUNTIFS('Launch Plan'!$A$5:$A$126,H22,'Launch Plan'!$K$5:$K$126,"In Progress")+COUNTIFS('Launch Plan'!$A$5:$A$126,H22,'Launch Plan'!$K$5:$K$126,"Not Started") -> 1 | J22: =COUNTIFS('Launch Plan'!$A$5:$A$126,H22,'Launch Plan'!$K$5:$K$126,"Complete") -> 0 | K22: =COUNTIFS('Launch Plan'!$A$5:$A$126,H22,'Launch Plan'!$K$5:$K$126,"In Progress") -> 0 | L22: =COUNTIFS('Launch Plan'!$A$5:$A$126,H22,'Launch Plan'!$K$5:$K$126,"Not Started") -> 1 | M22: =IFERROR(J22/I22,0) -> 0 | N22: =IF(M22=1,"READY",IF(K22>0,"MOVING",IF(M22>0,"PARTIAL","NOT STARTED"))) -> NOT STARTED
A26: GO / NO-GO GATES
A27: Green = passed | Amber = underway | Red = not passed / blocks launch decision
A29: Launch | B29: Gate | L29: Status | M29: Blocking? | N29: Decision
A30: ='Launch Plan'!A71 -> Alpha | B30: ='Launch Plan'!D71 -> PWA GATE: Alpha Habit-Stickiness passed | L30: ='Launch Plan'!K71 -> Not Started | M30: ='Launch Plan'!L71 -> Yes | N30: =IF(L30="Complete","GO",IF(L30="In Progress","WATCH","NO-GO")) -> NO-GO
A31: ='Launch Plan'!A72 -> PWA | B31: ='Launch Plan'!D72 -> PWA GATE: No Critical bugs open | L31: ='Launch Plan'!K72 -> Not Started | M31: ='Launch Plan'!L72 -> Yes | N31: =IF(L31="Complete","GO",IF(L31="In Progress","WATCH","NO-GO")) -> NO-GO
A32: ='Launch Plan'!A73 -> PWA | B32: ='Launch Plan'!D73 -> PWA GATE: Regression passed (real, non-zero test count) | L32: ='Launch Plan'!K73 -> Not Started | M32: ='Launch Plan'!L73 -> Yes | N32: =IF(L32="Complete","GO",IF(L32="In Progress","WATCH","NO-GO")) -> NO-GO
A33: ='Launch Plan'!A74 -> PWA | B33: ='Launch Plan'!D74 -> PWA GATE: Accessibility passed | L33: ='Launch Plan'!K74 -> Not Started | M33: ='Launch Plan'!L74 -> Yes | N33: =IF(L33="Complete","GO",IF(L33="In Progress","WATCH","NO-GO")) -> NO-GO
A34: ='Launch Plan'!A75 -> PWA | B34: ='Launch Plan'!D75 -> PWA GATE: Privacy Policy hosted AND deletion confirmed working | L34: ='Launch Plan'!K75 -> Not Started | M34: ='Launch Plan'!L75 -> Yes | N34: =IF(L34="Complete","GO",IF(L34="In Progress","WATCH","NO-GO")) -> NO-GO
A35: ='Launch Plan'!A76 -> PWA | B35: ='Launch Plan'!D76 -> PWA GATE: Support inbox staffed and monitored | L35: ='Launch Plan'!K76 -> Not Started | M35: ='Launch Plan'!L76 -> Yes | N35: =IF(L35="Complete","GO",IF(L35="In Progress","WATCH","NO-GO")) -> NO-GO
A36: ='Launch Plan'!A77 -> PWA | B36: ='Launch Plan'!D77 -> PWA GATE: Analytics clean (no undercounts, rollups un-blended) | L36: ='Launch Plan'!K77 -> Not Started | M36: ='Launch Plan'!L77 -> Yes | N36: =IF(L36="Complete","GO",IF(L36="In Progress","WATCH","NO-GO")) -> NO-GO
A37: ='Launch Plan'!A78 -> PWA | B37: ='Launch Plan'!D78 -> PWA GATE: Real-User Acquisition floor met, or explicit conscious-small-launch decision recorded | L37: ='Launch Plan'!K78 -> Not Started | M37: ='Launch Plan'!L78 -> Yes | N37: =IF(L37="Complete","GO",IF(L37="In Progress","WATCH","NO-GO")) -> NO-GO
A38: ='Launch Plan'!A79 -> PWA | B38: ='Launch Plan'!D79 -> PWA GATE: Founder approval, in writing, same day | L38: ='Launch Plan'!K79 -> Not Started | M38: ='Launch Plan'!L79 -> Yes | N38: =IF(L38="Complete","GO",IF(L38="In Progress","WATCH","NO-GO")) -> NO-GO
A39: ='Launch Plan'!A80 -> PWA | B39: ='Launch Plan'!D80 -> PWA GATE: ask-vet-assistant rate limiting / abuse protection shipped | L39: ='Launch Plan'!K80 -> Not Started | M39: ='Launch Plan'!L80 -> Yes | N39: =IF(L39="Complete","GO",IF(L39="In Progress","WATCH","NO-GO")) -> NO-GO
A40: ='Launch Plan'!A112 -> App Store | B40: ='Launch Plan'!D112 -> APP STORE GATE: PWA already passed Go/No-Go and ran 21+ consecutive clean usage days | L40: ='Launch Plan'!K112 -> Not Started | M40: ='Launch Plan'!L112 -> Yes | N40: =IF(L40="Complete","GO",IF(L40="In Progress","WATCH","NO-GO")) -> NO-GO
A41: ='Launch Plan'!A113 -> App Store | B41: ='Launch Plan'!D113 -> APP STORE GATE: Business Readiness complete | L41: ='Launch Plan'!K113 -> Not Started | M41: ='Launch Plan'!L113 -> Yes | N41: =IF(L41="Complete","GO",IF(L41="In Progress","WATCH","NO-GO")) -> NO-GO
A42: ='Launch Plan'!A114 -> App Store | B42: ='Launch Plan'!D114 -> APP STORE GATE: Capacitor builds pass internal testing, no Critical bugs | L42: ='Launch Plan'!K114 -> Not Started | M42: ='Launch Plan'!L114 -> Yes | N42: =IF(L42="Complete","GO",IF(L42="In Progress","WATCH","NO-GO")) -> NO-GO
A43: ='Launch Plan'!A115 -> App Store | B43: ='Launch Plan'!D115 -> APP STORE GATE: All Requirements items complete for both stores | L43: ='Launch Plan'!K115 -> Not Started | M43: ='Launch Plan'!L115 -> Yes | N43: =IF(L43="Complete","GO",IF(L43="In Progress","WATCH","NO-GO")) -> NO-GO
A44: ='Launch Plan'!A116 -> App Store | B44: ='Launch Plan'!D116 -> APP STORE GATE: Explicit decision recorded — still worth pursuing given PWA results? | L44: ='Launch Plan'!K116 -> Not Started | M44: ='Launch Plan'!L116 -> Yes | N44: =IF(L44="Complete","GO",IF(L44="In Progress","WATCH","NO-GO")) -> NO-GO
A47: SUB-BUCKET DETAIL
A49: Bucket | B49: Sub-Bucket | C49: Total | D49: Complete | E49: In Progress | F49: Not Started | G49: % Complete | H49: Signal
A50: PWA | B50: Launch Readiness | C50: =COUNTIFS('Launch Plan'!$A$5:$A$126,A50,'Launch Plan'!$B$5:$B$126,B50,'Launch Plan'!$K$5:$K$126,"Complete")+COUNTIFS('Launch Plan'!$A$5:$A$126,A50,'Launch Plan'!$B$5:$B$126,B50,'Launch Plan'!$K$5:$K$126,"In Progress")+COUNTIFS('Launch Plan'!$A$5:$A$126,A50,'Launch Plan'!$B$5:$B$126,B50,'Launch Plan'!$K$5:$K$126,"Not Started") -> 8 | D50: =COUNTIFS('Launch Plan'!$A$5:$A$126,A50,'Launch Plan'!$B$5:$B$126,B50,'Launch Plan'!$K$5:$K$126,"Complete") -> 8 | E50: =COUNTIFS('Launch Plan'!$A$5:$A$126,A50,'Launch Plan'!$B$5:$B$126,B50,'Launch Plan'!$K$5:$K$126,"In Progress") -> 0 | F50: =COUNTIFS('Launch Plan'!$A$5:$A$126,A50,'Launch Plan'!$B$5:$B$126,B50,'Launch Plan'!$K$5:$K$126,"Not Started") -> 0 | G50: =IFERROR(D50/C50,0) -> 1 | H50: =IF(G50=1,"READY",IF(E50>0,"MOVING",IF(G50>0,"PARTIAL","NOT STARTED"))) -> READY
A51: PWA | B51: Testing | C51: =COUNTIFS('Launch Plan'!$A$5:$A$126,A51,'Launch Plan'!$B$5:$B$126,B51,'Launch Plan'!$K$5:$K$126,"Complete")+COUNTIFS('Launch Plan'!$A$5:$A$126,A51,'Launch Plan'!$B$5:$B$126,B51,'Launch Plan'!$K$5:$K$126,"In Progress")+COUNTIFS('Launch Plan'!$A$5:$A$126,A51,'Launch Plan'!$B$5:$B$126,B51,'Launch Plan'!$K$5:$K$126,"Not Started") -> 15 | D51: =COUNTIFS('Launch Plan'!$A$5:$A$126,A51,'Launch Plan'!$B$5:$B$126,B51,'Launch Plan'!$K$5:$K$126,"Complete") -> 7 | E51: =COUNTIFS('Launch Plan'!$A$5:$A$126,A51,'Launch Plan'!$B$5:$B$126,B51,'Launch Plan'!$K$5:$K$126,"In Progress") -> 1 | F51: =COUNTIFS('Launch Plan'!$A$5:$A$126,A51,'Launch Plan'!$B$5:$B$126,B51,'Launch Plan'!$K$5:$K$126,"Not Started") -> 7 | G51: =IFERROR(D51/C51,0) -> 0.46666667 | H51: =IF(G51=1,"READY",IF(E51>0,"MOVING",IF(G51>0,"PARTIAL","NOT STARTED"))) -> MOVING
A52: PWA | B52: Go/No-Go | C52: =COUNTIFS('Launch Plan'!$A$5:$A$126,A52,'Launch Plan'!$B$5:$B$126,B52,'Launch Plan'!$K$5:$K$126,"Complete")+COUNTIFS('Launch Plan'!$A$5:$A$126,A52,'Launch Plan'!$B$5:$B$126,B52,'Launch Plan'!$K$5:$K$126,"In Progress")+COUNTIFS('Launch Plan'!$A$5:$A$126,A52,'Launch Plan'!$B$5:$B$126,B52,'Launch Plan'!$K$5:$K$126,"Not Started") -> 9 | D52: =COUNTIFS('Launch Plan'!$A$5:$A$126,A52,'Launch Plan'!$B$5:$B$126,B52,'Launch Plan'!$K$5:$K$126,"Complete") -> 0 | E52: =COUNTIFS('Launch Plan'!$A$5:$A$126,A52,'Launch Plan'!$B$5:$B$126,B52,'Launch Plan'!$K$5:$K$126,"In Progress") -> 0 | F52: =COUNTIFS('Launch Plan'!$A$5:$A$126,A52,'Launch Plan'!$B$5:$B$126,B52,'Launch Plan'!$K$5:$K$126,"Not Started") -> 9 | G52: =IFERROR(D52/C52,0) -> 0 | H52: =IF(G52=1,"READY",IF(E52>0,"MOVING",IF(G52>0,"PARTIAL","NOT STARTED"))) -> NOT STARTED
A53: PWA | B53: Product Decisions | C53: =COUNTIFS('Launch Plan'!$A$5:$A$126,A53,'Launch Plan'!$B$5:$B$126,B53,'Launch Plan'!$K$5:$K$126,"Complete")+COUNTIFS('Launch Plan'!$A$5:$A$126,A53,'Launch Plan'!$B$5:$B$126,B53,'Launch Plan'!$K$5:$K$126,"In Progress")+COUNTIFS('Launch Plan'!$A$5:$A$126,A53,'Launch Plan'!$B$5:$B$126,B53,'Launch Plan'!$K$5:$K$126,"Not Started") -> 1 | D53: =COUNTIFS('Launch Plan'!$A$5:$A$126,A53,'Launch Plan'!$B$5:$B$126,B53,'Launch Plan'!$K$5:$K$126,"Complete") -> 0 | E53: =COUNTIFS('Launch Plan'!$A$5:$A$126,A53,'Launch Plan'!$B$5:$B$126,B53,'Launch Plan'!$K$5:$K$126,"In Progress") -> 0 | F53: =COUNTIFS('Launch Plan'!$A$5:$A$126,A53,'Launch Plan'!$B$5:$B$126,B53,'Launch Plan'!$K$5:$K$126,"Not Started") -> 1 | G53: =IFERROR(D53/C53,0) -> 0 | H53: =IF(G53=1,"READY",IF(E53>0,"MOVING",IF(G53>0,"PARTIAL","NOT STARTED"))) -> NOT STARTED
...

Sheet Launch Plan
A1: Wysker Watch — Launch Plan (Single Tab)
A2: PWA launch is its own Go/No-Go, independent of App Store. Gates rebuilt from scratch (yellow = draft, confirm before it blocks). Filter by Bucket or Status using the header dropdowns. Rows tagged 'GATE' are blocking checkpoints, not tasks.
A4: Bucket | B4: Sub-Bucket | C4: Task ID | D4: Item | E4: Type | F4: Owner | G4: Priority | H4: Start Date | I4: Duration | J4: End Date | K4: Status | L4: Blocking? | M4: Draft/Notes
A5: PWA | B5: Launch Readiness | C5: 1 | D5: Host Privacy Policy at wyskerwatch.com/privacy | E5: Task | F5: Lynn | G5: Critical | H5: 46243 | I5: 5 | J5: =H5+I5 -> 46248 | K5: Complete | L5: Yes | M5: Depends on the deletion-function confirmation above.
A6: PWA | B6: Launch Readiness | C6: 2 | D6: Host Terms of Service at wyskerwatch.com/terms | E6: Task | F6: Lynn | G6: Critical | H6: 46243 | I6: 5 | J6: =H6+I6 -> 46248 | K6: Complete | L6: Yes | M6: Mirrors the Privacy Policy hosting task. In-app /terms route + signup consent gate (spec 0047) already exist; confirm the marketing-domain page too.
A7: PWA | B7: Launch Readiness | C7: 3 | D7: Set up support@wyskerwatch.com inbox | E7: Task | F7: Lynn | G7: High | H7: 46243 | I7: 7 | J7: =H7+I7 -> 46250 | K7: Complete | L7: Yes | M7: Still on backlog.
A8: PWA | B8: Launch Readiness | C8: 4 | D8: Confirm backend changes pushed to all 3 Supabase projects (dev/staging/prod) | E8: Task | F8: Lynn (Claude Code) | G8: High | H8: 46243 | I8: 7 | J8: =H8+I8 -> 46250 | K8: Complete | L8: Yes | M8: Has been missed before per project docs.
A9: PWA | B9: Launch Readiness | C9: 5 | D9: Confirm production Cloudflare Worker env vars (Supabase URL/key etc.) via real prod smoke test | E9: Task | F9: Lynn | G9: High | H9: 46243 | I9: 7 | J9: =H9+I9 -> 46250 | K9: Complete | L9: Yes | M9: wrangler.jsonc declares no secrets/bindings in-repo; presumably set in Cloudflare dashboard. Two deploy paths now exist (dashboard build vs. new "npm run deploy" script) — confirm which is authoritative before relying on either.
A10: PWA | B10: Launch Readiness | C10: 6 | D10: Schedule a recurring (e.g. quarterly) DB restore-drill cadence | E10: Task | F10: Lynn | G10: Low | H10: 46243 | I10: 10 | J10: =H10+I10 -> 46253 | K10: Complete | L10: No | M10: Restore pipeline is implemented and was verified once end-to-end, but only manual-trigger — no automated recurring drill is scheduled.
A11: PWA | B11: Launch Readiness | C11: 7 | D11: Document the Cloudflare manual-deploy gate (exact dashboard path, who has access) in-repo | E11: Task | F11: Lynn | G11: Medium | H11: 46243 | I11: 10 | J11: =H11+I11 -> 46253 | K11: Complete | L11: Yes | M11: Gate exists in production but has zero in-repo representation — known only to Lynn. Bus-factor risk for launch-day and post-launch deploys.
A12: PWA | B12: Launch Readiness | C12: 8 | D12: Decide: storage-bucket file (pet photo/document) backup coverage for launch, or explicit accepted-risk | E12: Task | F12: Lynn | G12: Medium | H12: 46243 | I12: 10 | J12: =H12+I12 -> 46253 | K12: Complete | L12: Yes | M12: Nightly pg_dump-to-R2 backup (P0, resolved) explicitly excludes storage bucket files — see requirements-database-backups.md and Risk row below. No task currently owns closing or consciously accepting this gap, unlike the equivalent GDPR-export decision row above. Needs the same explicit in/out-of-scope call.
A13: PWA | B13: Launch Readiness | C13: 9 | D13: Investigate PWA SEO | E13: Task | F13: Lynn | G13: Medium | H13: 46243 | I13: 10 | J13: =H13+I13 -> 46253 | K13: Blocked | L13: Yes | M13: Need to understand how easy it is to put SEO into the PWA. Because of the browser bug, I don't think I can do this.
A14: Analytics & Support | B14: Analytics | C14: 10 | D14: Validate hourly rollup against raw event log for one full day | E14: Task | F14: Lynn (Claude Code) | G14: Medium | H14: 46243 | I14: 14 | J14: =H14+I14 -> 46257 | K14: Complete | L14: No | M14: Sanity check before trusting the dashboard.
A15: Analytics & Support | B15: Support | C15: 11 | D15: Set up support@wyskerwatch.com inbox | E15: Task | F15: Lynn | G15: High | H15: 46243 | I15: 14 | J15: =H15+I15 -> 46257 | K15: Complete | L15: Yes | M15: Committed to in the Privacy Policy.
A16: Analytics & Support | B16: Support | C16: 12 | D16: Draft a minimal FAQ / help page | E16: Task | F16: Lynn | G16: Low | H16: 46243 | I16: 14 | J16: =H16+I16 -> 46257 | K16: Complete | L16: No | M16: Reduces first-week support load.
... A28: PWA | B28: Testing | C28: 24 | D28: Device / browser compatibility (iOS Safari + Android Chrome PWA install path) | E28: Task | F28: Lynn | G28: High | H28: 46257 | I28: 14 | J28: =H28+I28 -> 46271 | K28: Not Started | L28: Yes | M28: iOS install is manual-banner only — verify it still works.
A29: PWA | B29: Testing | C29: 25 | D29: Accessibility pass (44px targets, contrast, never color-only) | E29: Task | F29: Lynn | G29: High | H29: 46257 | I29: 14 | J29: =H29+I29 -> 46271 | K29: Not Started | L29: Yes
A30: PWA | B30: Testing | C30: 26 | D30: Performance pass | E30: Task | F30: Lynn | G30: Medium | H30: 46257 | I30: 14 | J30: =H30+I30 -> 46271 | K30: Not Started | L30: No
A31: PWA | B31: Testing | C31: 27 | D31: Feature Freeze | E31: Milestone | F31: Lynn | G31: Critical | H31: 46257 | I31: 1 | J31: =H31+I31 -> 46258 | K31: Not Started | L31: Yes | M31: Reconcile against Claude Code's actual repo state before freezing.
A32: User Funnel | B32: Definitions | C32: 28 | D32: Alpha = Friend + Stranger Cohort, validates habit stickiness | E32: Reference | F32: - | G32: - | H32: 46243 | I32: 14 | J32: =H32+I32 -> 46257 | K32: Not Started | L32: - | M32: Feeds PWA Go/No-Go gate.
A33: Social & Content | B33: Pipeline | C33: 29 | D33: Confirm Claude -> Canva -> Buffer pipeline end-to-end | E33: Task | F33: Lynn | G33: Medium | H33: 46243 | I33: 5 | J33: =H33+I33 -> 46248 | K33: Not Started | L33: No | M33: Confirm before relying on it for launch week.
A34: Business Readiness | B34: Formation | C34: 31 | D34: Rename LLC | E34: Task | F34: Lynn | G34: Critical | H34: 46243 | I34: 14 | J34: =H34+I34 -> 46257 | K34: Complete | L34: For App Store | M34: Needed before D-U-N-S / Apple entity verification.
A35: Business Readiness | B35: Formation | C35: 32 | D35: Add DBA | E35: Task | F35: Lynn | G35: Critical | H35: 46243 | I35: 14 | J35: =H35+I35 -> 46257 | K35: Not Started | L35: For App Store | M35: Add Wysker Watch as DBA under Double Diamond Works
A36: Business Readiness | B36: Formation | C36: 33 | D36: Obtain EIN | E36: Task | F36: Lynn | G36: Critical | H36: 46243 | I36: 14 | J36: =H36+I36 -> 46257 | K36: Not Started | L36: For App Store | M36: Free via IRS.gov once LLC exists.
A37: Business Readiness | B37: Banking | C37: 34 | D37: Open business bank account | E37: Task | F37: Lynn | G37: High | H37: 46243 | I37: 14 | J37: =H37+I37 -> 46257 | K37: Not Started | L37: For App Store
A38: Social & Content | B38: Launch Campaign | C38: 35 | D38: Post-launch content cadence | E38: Task | F38: Lynn | G38: Medium | H38: 46243 | J38: =H38+I38 -> 46243 | K38: Not Started | L38: No
A39: Risk | B39: Register | C39: 36 | D39: Daily check-in habit doesn't stick with Stranger Cohort | E39: Risk | F39: Lynn | G39: High | H39: 46243 | I39: 21 | J39: =H39+I39 -> 46264 | K39: Not Started | L39: - | M39: Now the PWA Gate's Product row — hard checkpoint. If it fires, Alpha extends before PWA launches.
A40: Risk | B40: Register | C40: 37 | D40: Critical production bug at or near PWA launch | E40: Risk | F40: Lynn | G40: High | H40: 46243 | I40: 21 | J40: =H40+I40 -> 46264 | K40: Not Started | L40: - | M40: Regression + device compatibility testing completed before Feature Freeze.
A41: Risk | B41: Register | C41: 38 | D41: AI Assistant quality concerns | E41: Risk | F41: Lynn | G41: High | H41: 46243 | I41: 21 | J41: =H41+I41 -> 46264 | K41: Not Started | L41: - | M41: Adversarial/edge-case prompt set required in the QA test plan.
A42: Risk | B42: Register | C42: 39 | D42: Real-user acquisition insufficient | E42: Risk | F42: Lynn | G42: High | H42: 46243 | I42: 21 | J42: =H42+I42 -> 46264 | K42: Not Started | L42: - | M42: Real-User Acquisition floor gate row; Watch List campaign must be live and tracked ahead of launch.
A43: Risk | B43: Register | C43: 40 | D43: Single founder covering Engineering, QA, Business, Support | E43: Risk | F43: Lynn | G43: High | H43: 46243 | I43: 21 | J43: =H43+I43 -> 46264 | K43: Not Started | L43: - | M43: Partially resolved — 2nd person now named for launch-day Support + Bug Triage.
A44: Risk | B44: Register | C44: 41 | D44: Apple rejection during App Store review | E44: Risk | F44: Lynn | G44: High | H44: 46243 | I44: 21 | J44: =H44+I44 -> 46264 | K44: Not Started | L44: - | M44: TestFlight testing before submission; review current Apple guidelines close to submission time.
A45: Risk | B45: Register | C45: 42 | D45: D-U-N-S / Apple entity verification delays App Store timeline | E45: Risk | F45: Lynn | G45: High | H45: 46243 | I45: 21 | J45: =H45+I45 -> 46264 | K45: Not Started | L45: - | M45: Does not block PWA launch. Start LLC/D-U-N-S early regardless.
A46: Risk | B46: Register | C46: 43 | D46: Support inbox unmonitored during first weeks post-launch | E46: Risk | F46: Lynn | G46: High | H46: 46243 | I46: 21 | J46: =H46+I46 -> 46264 | K46: Not Started | L46: - | M46: Staffed as part of Launch Day + week-one cadence.
A47: Risk | B47: Register | C47: 44 | D47: ask-vet-assistant has no rate limiting or abuse protection | E47: Risk | F47: Lynn | G47: High | H47: 46243 | I47: 21 | J47: =H47+I47 -> 46264 | K47: Complete | L47: - | M47: Any authenticated account (test, demo, real) can call it unlimited times; each call is a real, billed Anthropic API request. No per-user/per-window cap exists in the Edge Function.
A48: Risk | B48: Register | C48: 45 | D48: No production error/crash monitoring wired up (no Sentry or equivalent) | E48: Risk | F48: Lynn | G48: High | H48: 46243 | I48: 21 | J48: =H48+I48 -> 46264 | K48: Complete | L48: - | M48: No client-side JS error capture or server-side error aggregation/alerting. Launch Day Runbook currently relies on manual "Monitor analytics" only.
A49: Risk | B49: Register | C49: 46 | D49: Pet photo/document storage files have zero backup coverage | E49: Risk | F49: Lynn | G49: Medium | H49: 46243 | I49: 21 | J49: =H49+I49 -> 46264 | K49: Not Started | L49: - | M49: DB backup pipeline (nightly pg_dump to R2) is implemented, but storage-bucket files are explicitly excluded. Restore drills are also manual-trigger only, not scheduled.
A50: Risk | B50: Register | C50: 47 | D50: Cloudflare manual-deploy gate exists only in dashboard, undocumented | E50: Risk | F50: Lynn | G50: Medium | H50: 46243 | I50: 21 | J50: =H50+I50 -> 46264 | K50: Not Started | L50: - | M50: Single point of knowledge (Lynn only). Exact settings/access list not recorded in-repo. Bus-factor risk for launch-day and post-launch deploys.
... A68: Social & Content | B68: Launch Campaign | C68: 65 | D68: Watch List / signup campaign live and tracked | E68: Task | F68: Lynn | G68: High | H68: 46264 | I68: 14 | J68: =H68+I68 -> 46278 | K68: Not Started | L68: Yes | M68: Must be live and tracked, not just planned. Confirmed 2026-08-15 (spec 0056): this is the pre-App-Store-phase Watch List, a separate later list not built yet. Distinct from /early-adopters (spec 0056, shipped 2026-08-15), the pre-PWA-launch signup page for general social traffic — do not conflate the two.
A69: Social & Content | B69: Launch Campaign | C69: 66 | D69: Launch day posts scheduled | E69: Task | F69: Lynn | G69: High | H69: 46264 | I69: 14 | J69: =H69+I69 -> 46278 | K69: Not Started | L69: Yes
...

Sheet Pre-Alpha Audit
A1: Wysker Watch — Pre-Alpha Audit Punch List
A2: Combined from spec 0068 (deployed-state audit) and spec 0069 (security review), 2026-10-23. P0 = fix before alpha kickoff on 2026-11-02. Each fix needs its own spec and Lynn's review before any code is written. Filter with the header dropdowns.
A4: Item ID | B4: Rank | C4: Area | D4: Item | E4: Source | F4: Owner | G4: Fix Type | H4: Status | I4: Blocks Alpha? | J4: Fix Spec | K4: Notes
A5: PA-01 | B5: P0 | C5: Storage | D5: Make the uploads bucket private. Anyone, even logged out, can currently list and download every pet photo and scanned vet document. | E5: 0068 P0-1 | F5: Lynn (Claude Code) | G5: Migration + Frontend + Edge Function | H5: Not Started | I5: Yes | J5: Not written | K5: Switch to short-lived signed links (storageClient.js), store file paths instead of public URLs, add a size cap and image/PDF-only rule. ask-vet-assistant must download files server-side. Also covers 0069's note that observation photo links accept any outside URL.
A6: PA-02 | B6: P0 | C6: Access control | D6: Stop strangers from making themselves a pet's co-owner. Any signed-in user who knows a pet's ID can add themselves, invisibly, and then edit or delete the pet. | E6: 0068 P0-2 | F6: Lynn (Claude Code) | G6: Migration | H6: Not Started | I6: Yes | J6: Not written | K6: Insert rule must require the caller to already own the pet, and only the invite-claim step may link a user. Let every owner of a pet see all its co-owners. Add a stranger test (test1@ on test4@'s pet must fail).
A7: PA-03 | B7: P0 | C7: Access control | D7: Stop strangers from giving themselves read access to any pet through a fake pet-sit. | E7: 0068 P0-3 | F7: Lynn (Claude Code) | G7: Migration | H7: Not Started | I7: Yes | J7: Not written | K7: Pet-sit and sitter-access rules must require the caller to own every pet in the sit, not just one. Same fix spec as PA-04.
A8: PA-04 | B8: P0 | C8: Access control | D8: Make sitter access end when the sit ends. Today a sitter can read the pet's profile and every future check-in forever, which contradicts the Privacy Policy. | E8: 0069 P0-1 | F8: Lynn (Claude Code) | G8: Migration + Decision | H8: Not Started | I8: Yes | J8: Not written | K8: Add the sit's date range to the sitter-access check. Decision needed from Lynn: should sitters see the pet before the sit starts, and for how long after it ends? Prod has 0 sits today.
A9: PA-05 | B9: P0 | C9: Database functions | D9: Lock down server-only database functions that anyone, even logged out, can call. One of them lets a stranger permanently block email to any address. | E9: 0068 P0-4, P1-7, P2; 0069 P2 | F9: Lynn (Claude Code) | G9: Migration + Edge Function | H9: Not Started | I9: Yes | J9: Not written | K9: Revoke access from logged-out and logged-in users on every server-only function (staging is already correct, prod and dev aren't). Stop returning the email message ID to the browser. Rewrite the owner/sitter check functions to use the caller's own ID. Note: password resets are not affected by the email block (0069 correction).
A10: PA-06 | B10: P0 | C10: Data lifecycle | D10: Stop account deletion from erasing records the person entered on a shared pet (check-ins, observations, vaccinations). | E10: 0068 P0-5 | F10: Lynn (Claude Code) | G10: Migration + Tests | H10: Not Started | I10: Yes | J10: Not written | K10: Change the 'entered by' links on the record tables from 'delete with the account' to 'keep the record, clear the name'. Tests must have the departing person enter real records first and confirm they survive.
A11: PA-07 | B11: P0 | C11: Data lifecycle | D11: Fix delete-account so other co-owners keep access and the transferred pet keeps its photo and documents. | E11: 0068 P0-6; 0068 P2 | F11: Lynn (Claude Code) | G11: Edge Function + Tests | H11: Not Started | I11: Yes | J11: Not written | K11: Share one co-owner transfer helper with delete-pet (which already does this right). Move, don't delete, files belonging to transferred pets. Handle more than 100 files. Also fix the partial-failure case and the misleading header comment. Add a 3-person test with a photo and a scanned document.
A12: PA-08 | B12: P0 | C12: First-run journey | D12: Make the Terms and Privacy pages open for signed-out visitors. The links on the signup screen currently bounce to the login page. | E12: 0068 P0-7 | F12: Lynn (Claude Code) | G12: Frontend | H12: Not Started | I12: Yes | J12: Not written | K12: Move the 4 legal page routes outside the logged-in section of App.jsx. Add one Playwright test. Run design-system-check.
A13: PA-09 | B13: P0 | C13: First-run journey | D13: Make sure friend testers can reset a forgotten password, and that the app tells them if the reset email fails. | E13: 0069 P0-2 | F13: Lynn / Claude Code | G13: Dashboard check + Frontend | H13: Not Started | I13: Yes | J13: Not written | K13: Lynn: check Supabase > prod > Authentication > Emails > SMTP Settings. If custom SMTP is off, Supabase's built-in mailer only delivers to team addresses. Code: ForgotPassword.jsx currently always says 'sent', even when it failed.
A14: PA-10 | B14: P1 | C14: Abuse & cost | D14: Add ownership checks and a rate limit to the co-owner and sitter invite emails. Any signed-in user can send branded email to any address with no limit. | E14: 0068 P1-1 | F14: Lynn (Claude Code) | G14: Edge Function | H14: Not Started | I14: No | J14: Not written | K14: Check the caller owns the pet (and look up the pet name server-side). Add a per-user limit (e.g. 10 an hour). Give the same response whether or not the address has an account.
A15: PA-11 | B15: P1 | C15: Abuse & cost | D15: Close the open AI proxy. Any signed-in user can send any prompt to Claude, and the endpoint will fetch any URL it's given. | E15: 0068 P1-2 | F15: Lynn / Claude Code | G15: Edge Function + Dashboard | H15: Not Started | I15: No | J15: Not written | K15: Move prompts and safety rules server-side, only accept this project's own file links with a size cap, add a daily per-user cap, and report AI failures to Sentry. Lynn: set a monthly spend limit in the Anthropic console.
... A27: PA-23 | B27: P1 | C27: Docs | D27: Correct spec 0066's 'identical across all 3 projects' result and 0068 P0-4's 'password resets' wording. | E27: 0068 docs drift; 0069 docs drift | F27: Lynn (Claude Code) | G27: Docs | H27: Not Started | I27: No | J27: Not written | K27: Function permissions differed (see PA-05). Password resets go through Supabase's own mailer, so they aren't blocked by the fake-bounce issue. PR #22 (merged 2026-10-24) still carries the 'identical' wording in 0066's Results. Root cause: 0066's step-0 check compared function code and security settings, but not who may run each function.
A28: PA-24 | B28: P2 | C28: Access control | D28: Limit what co-owners can do: today any co-owner can hand the pet's primary ownership to anyone, or delete the pet directly, skipping the transfer logic. | E28: 0068 P2 | F28: Lynn (Claude Code) | G28: Migration | H28: Not Started | I28: No | J28: Not written
A29: PA-25 | B29: P2 | C29: Access control | D29: Make the 'entered by' field on new records always the person actually signed in. | E29: 0068 P2 | F29: Lynn (Claude Code) | G29: Migration | H29: Not Started | I29: No | J29: Not written
A30: PA-26 | B30: P2 | C30: Access control | D30: Make sure sitter log entries can only be attached to pets in that sit. | E30: 0069 P2 | F30: Lynn (Claude Code) | G30: Migration | H30: Not Started | I30: No | J30: Not written
A31: PA-27 | B31: P2 | C31: Access control | D31: Make profile email read-only and match sitter invites on the verified login email. | E31: 0069 P2 | F31: Lynn (Claude Code) | G31: Migration | H31: Not Started | I31: No | J31: Not written | K31: Today someone could change their profile email to another person's and see that person's sitter-invite rows (no pet data).
A32: PA-28 | B32: P2 | C32: Features | D32: Keep sitter-only pets out of owner-only flows (Scan Record matching, Edit Pet, Vet Report). | E32: 0069 P2 | F32: Lynn (Claude Code) | G32: Frontend | H32: Not Started | I32: No | J32: Not written
A33: PA-29 | B33: P2 | C33: Database functions | D33: Set a fixed search path on 3 database functions (security-scanner warning). | E33: 0068 P2 | F33: Lynn (Claude Code) | G33: Migration | H33: Not Started | I33: No | J33: Not written | K33: handle_new_user, classify_account_type, set_updated_at.
A34: PA-30 | B34: P2 | C34: Account security | D34: Turn on leaked-password protection in Supabase Auth. | E34: 0068 P2 | F34: Lynn | G34: Dashboard | H34: Not Started | I34: No | J34: Not written | K34: One toggle, under Authentication > Attack Protection.
A35: PA-31 | B35: P2 | C35: Abuse & cost | D35: Add the CAPTCHA to Register and 'resend confirmation' to stop inbox flooding. | E35: 0069 P2 | F35: Lynn (Claude Code) | G35: Frontend + Edge Function | H35: Not Started | I35: No | J35: Not written | K35: Same Turnstile already used on /beta.
A36: PA-32 | B36: P2 | C36: Abuse & cost | D36: Check that per-visitor signup limits see the real visitor's address, not Supabase's proxy. | E36: 0069 P2 | F36: Lynn (Claude Code) | G36: Investigation | H36: Not Started | I36: No | J36: Not written | K36: If they see the proxy, every visitor shares one limit, and signups would be refused site-wide after 20 an hour.
A37: PA-33 | B37: P2 | C37: Abuse & cost | D37: Cap analytics event writes and exclude demo accounts from the analytics summary. | E37: 0068 P2; 0069 P2 | F37: Lynn (Claude Code) | G37: Migration | H37: Not Started | I37: No | J37: Not written
A38: PA-34 | B38: P2 | C38: Silent failures | D38: Flush Sentry before backend functions return, so events aren't dropped. | E38: 0068 P2 | F38: Lynn (Claude Code) | G38: Edge Function | H38: Not Started | I38: No | J38: Not written
A39: PA-35 | B39: P2 | C39: Silent failures | D39: Return generic error messages from backend functions instead of internal details. | E39: 0069 P2 | F39: Lynn (Claude Code) | G39: Edge Function | H39: Not Started | I39: No | J39: Not written | K39: Sentry already gets the detail.
A40: PA-36 | B40: P2 | C40: Features | D40: Notify existing users when they're added as a co-owner. Today they get no email or notice, and only see the pet after their next login. | E40: 0068 P2 | F40: Lynn (Claude Code) | G40: Edge Function + Frontend | H40: Not Started | I40: No | J40: Not written
A41: PA-37 | B41: P2 | C41: Config | D41: Confirm the 'nightly-analytics-summary' job is meant to run every hour. | E41: 0068 P2 | F41: Lynn | G41: Decision | H41: Not Started | I41: No | J41: Not written | K41: It has run 336 times in 14 days.
A42: PA-38 | B42: P2 | C42: Account security | D42: Decide how far the shared demo login should reach. It's a real, writable prod session. | E42: 0069 P2 | F42: Lynn | G42: Decision | H42: Not Started | I42: No | J42: Not written | K42: Depends on who has the demo1@ password and whether it's published anywhere.
A43: PA-39 | B43: P2 | C43: Code health | D43: Move duplicated helpers into _shared, and wire in or delete the unused password-reset email template. | E43: 0069 repo note | F43: Lynn (Claude Code) | G43: Refactor | H43: Not Started | I43: No | J43: Not written | K43: Helpers: getJwtRole (2 copies); getRequestIp and verifyTurnstile (3 copies).
A44: PA-40 | B44: P2 | C44: Docs | D44: Fix 4 stale CLAUDE.md notes. | E44: 0068 docs drift | F44: Lynn (Claude Code) | G44: Docs | H44: Not Started | I44: No | J44: Not written | K44: Start-here path doesn't exist. The e2e 'trial through 9/3' note is stale (the job has never passed). Planner file vs Execution Plan memory needs a decision. Add a note that 0052's restored public-read rule is itself a P0.
A45: PA-41 | B45: Check | C45: Dashboard checks | D45: Run the Supabase Auth dashboard checklist on prod, then dev and staging. | E45: 0068 OQ1; 0069 OQ2 | F45: Lynn | G45: Dashboard check | H45: Not Started | I45: No | J45: Not written | K45: Secure email change on; link expiry 1 hour or less; Site URL and redirect list exact (no localhost or wildcards on prod); email rate limit; refresh-token reuse detection on.
A46: PA-42 | B46: Check | C46: Dashboard checks | D46: Confirm the live production frontend on Cloudflare is the current main build (c36f7a4). | E46: 0068 OQ2 | F46: Lynn | G46: Dashboard check | H46: Not Started | I46: No | J46: Not written | K46: Promotion is manual, and I can't see it from here.
A47: PA-43 | B47: Check | C47: Dashboard checks | D47: Rotate the test1@/test2@ passwords that were shared in a chat, and update the matching GitHub secrets. | E47: 0066 open question | F47: Lynn | G47: Dashboard | H47: Not Started | I47: No | J47: Not written | K47: Lynn, 2026-10-24: rotating soon. Update .env.playwright and the GitHub secrets (PLAYWRIGHT_TEST1_PASSWORD, SUPABASE_DEV_TEST2_PASSWORD) at the same time.
A48: PA-44 | B48: P1 | C48: Testing | D48: Build spec 0067: get the e2e check green. It has failed on every PR since it was added on 2026-08-15. | E48: 0067 (approved 2026-10-21) | F48: Lynn (Claude Code) | G48: Frontend + Tests + CI | H48: Not Started | I48: No | J48: 0067 approved | K48: Causes: the /beta Submit button moves 69px when the CAPTCHA finishes (a real visitor bug too), Early Adopters test checks a removed heading, CI never gets the test4@ login, vaccination tests can't seed data in CI (will be skipped there). Needs PA-45 for its last two checks.
A49: PA-45 | B49: P1 | C49: Testing | D49: Update the GitHub secrets the e2e job uses: re-enter PLAYWRIGHT_TEST3_ADMIN_EMAIL/PASSWORD and add PLAYWRIGHT_TEST4_SITTER_EMAIL/PASSWORD. | E49: 0067 AC4/AC5 | F49: Lynn | G49: Dashboard | H49: Not Started | I49: No | J49: 0067 | K49: Copy values from .env.playwright. GitHub > repo > Settings > Secrets and variables > Actions. Do it with PA-43 so CI gets the rotated passwords too.
A50: PA-46 | B50: P2 | C50: Testing | D50: Cache Playwright's browsers in the CI e2e job, so a slow package server can't time it out. | E50: PR #22 CI run, 2026-10-23 | F50: Lynn (Claude Code) | G50: CI | H50: Not Started | I50: No | J50: Not written | K50: On PR #22 the job spent its full 20-minute limit downloading Ubuntu packages and was cancelled before any test ran. Not in 0067's scope; raise when 0067 is built.
A51: PA-47 | B51: P2 | C51: Testing | D51: Redo the abandoned PR #19/#20 work: the vaccination e2e test should refuse to run unless the CLI is linked to dev, and should clean up its test data even when a test fails. | E51: Closed PRs #19/#20 (built without spec review) | F51: Lynn (Claude Code) | G51: Tests | H51: Not Started | I51: No | J51: Not written | K51: Needs a new spec Lynn reviews first. Branches claude/cranky-ptolemy-795759 and claude/xenodochial-bell-d19ae3 are still on GitHub for reference.
A52: PA-48 | B52: P2 | C52: Testing | D52: Investigate e2e tests that fail only sometimes (check-in history on 09-01; bottom nav, home cards and pet editing on 08-19). | E52: 0067 non-goal | F52: Lynn (Claude Code) | G52: Investigation | H52: Not Started | I52: No | J52: Not written | K52: Best done after PA-44, so real failures stand out.
...
